2023-10-26 12:25:00,229 - instabot version: 0.117.0 (api_login) - INFO - LOGIN FLOW! Just logged-in: False
2023-10-26 12:25:00,305 - instabot version: 0.117.0 (api_login) - ERROR - Error loginin, exception raised: 'API' object has no attribute 'uuid'
Traceback (most recent call last):
  File "C:\Users\USER\Desktop\Insta _Bot\insta_bot_unfollower\venv\Lib\site-packages\instabot\api\api_login.py", line 255, in login_flow
    self.get_timeline_feed(
  File "C:\Users\USER\Desktop\Insta _Bot\insta_bot_unfollower\venv\Lib\site-packages\instabot\api\api.py", line 750, in get_timeline_feed
    "X-DEVICE-ID": self.uuid,
                   ^^^^^^^^^
AttributeError: 'API' object has no attribute 'uuid'

2023-10-26 12:25:05,277 - instabot version: 0.117.0 (api_login) - INFO - Not yet logged in starting: PRE-LOGIN FLOW!
2023-10-26 12:25:08,286 - instabot version: 0.117.0 (api) - DEBUG - POST to endpoint: accounts/get_prefill_candidates/ returned response: <Response [429]>
2023-10-26 12:25:08,287 - instabot version: 0.117.0 (api) - DEBUG - Responsecode indicates error; response content: b'{"message":"Please wait a few minutes before you try again.","status":"fail"}'
2023-10-26 12:25:08,287 - instabot version: 0.117.0 (api) - ERROR - Request returns 429 error!
2023-10-26 12:25:08,289 - instabot version: 0.117.0 (api) - WARNING - That means 'too many requests'. I'll go to sleep for 5 minutes.
